Workbook

Sheet RAW
A1: ID | B1: Start time | C1: Completion time | D1: Email | E1: Name | F1: Last modified time | G1: Sebutkan kode Cabang/Network Anda | H1: Berapa jumlah Kendaraan Operasional (Bukan OCOP) yang Ada di Cabang/Network Anda? | I1: Tipe Kendaraan1 | J1: Nopol1 | K1: KM Berjalan1 | L1: Apakah Servis?1 | M1: Tanggal Service1 | N1: KM Servis1 | O1: Upload Bukti Service (SPK/Kartu Service) Network Anda pada Bulan Desember! | P1: Upload Bukti KM (kilometer) Terakhir Kendaraan Cabang Anda! | Q1: Tipe Kendaraan2 | R1: Nopol2 | S1: KM Berjalan2 | T1: Apakah Servis?2 | U1: Tanggal Service2 | V1: KM Servis2 | W1: Upload Bukti Service (SPK/Kartu Service) Network Anda pada Bulan Desember!2 | X1: Upload Bukti KM (kilometer) Terakhir Kendaraan Cabang Anda!2 | Y1: Tipe Kendaraan3 | Z1: Nopol3 | AA1: KM Berjalan3 | AB1: Apakah Servis?3 | AC1: Tanggal Service3 | AD1: KM Servis3 | AE1: Upload Bukti Service (SPK/Kartu Service) Network Anda pada Bulan Desember!3 | AF1: Upload Bukti KM (kilometer) Terakhir Kendaraan Cabang Anda!3
A2: 1 | B2: 45859.684 | C2: 45859.686 | D2: 29592@armadanusantara.co.id | E2: Taufik Utama | G2: 10597 NABIRE UNIT | H2: 1 | Y2: DAIHATSU GRANMAX PU AC PS 1.5 M/T | Z2: B8069JR | AA2: 83521 | AB2: Iya | AC2: 45859 | AD2: 83521 | AE2: https://files.armadanusantara.co.id/bukti/e66afb2aa719.jpeg | AF2: https://files.armadanusantara.co.id/bukti/670101dbdc3d.jpg
A3: 2 | B3: 45859.687 | C3: 45859.69 | D3: 38466@armadanusantara.co.id | E3: Raka Halim | G3: 35309 SERANG 2 | H3: 1 | Y3: PICK UP TRAGA 2.5 4X2 MT D M/T | Z3: B3406ZUA | AA3: 49892 | AB3: Iya | AC3: 45810 | AD3: 49892 | AE3: https://files.armadanusantara.co.id/bukti/3fa4161eca13.pdf | AF3: https://files.armadanusantara.co.id/bukti/54caa6a6f665.pdf
A4: 3 | B4: 45859.687 | C4: 45859.692 | D4: 15826@armadanusantara.co.id | E4: Budi Iskandar | G4: 42127 INDRAGIRI HULU | H4: 1 | Y4: PICK UP TRAGA 2.5 4X2 MT D M/T | Z4: H6818GV | AA4: 27693 | AB4: Iya | AC4: 45821 | AD4: 27693 | AE4: https://files.armadanusantara.co.id/bukti/4fa5bcf8083d.jpg | AF4: https://files.armadanusantara.co.id/bukti/95d5789aced8.png
A5: 4 | B5: 45859.689 | C5: 45859.692 | D5: 81569@armadanusantara.co.id | E5: Eka Hidayat | G5: 19849 BANYUWANGI POS | H5: 1 | Y5: PICK UP TRAGA 2.5 4X2 MT D M/T | Z5: B4597RJ | AA5: 69984 | AB5: Iya | AC5: 45859 | AD5: 69984 | AE5: https://files.armadanusantara.co.id/bukti/d104fafe826e.jpeg | AF5: https://files.armadanusantara.co.id/bukti/6c87c120d449.jpeg
A6: 5 | B6: 45859.685 | C6: 45859.692 | D6: 64039@armadanusantara.co.id | E6: Irfan Maulana | G6: 27732 KETAPANG | H6: 1 | Y6: DAIHATSU GRANMAX PU AC PS 1.5 M/T | Z6: AB7714BG | AA6: 46830 | AB6: Iya | AC6: 45798 | AD6: 46830 | AE6: https://files.armadanusantara.co.id/bukti/f594c653e469.jpg | AF6: https://files.armadanusantara.co.id/bukti/038938b96cf3.jpg
A7: 6 | B7: 45859.684 | C7: 45859.695 | D7: 26694@armadanusantara.co.id | E7: Novi Saputra | G7: 13597 GRESIK | H7: 1 | Y7: DAIHATSU GRANMAX PU AC PS 1.5 M/T | Z7: B1204ZZ | AA7: 17526 | AB7: Iya | AC7: 45841 | AD7: 17526 | AE7: https://files.armadanusantara.co.id/bukti/074f3a96f5eb.jpeg | AF7: https://files.armadanusantara.co.id/bukti/92036338f10d.png
A8: 7 | B8: 45859.696 | C8: 45859.699 | D8: 40080@armadanusantara.co.id | E8: Arif Zulkarnain | G8: 86545 SUNGAILIAT | H8: 2 | Q8: Daihatsu Xenia (Badan) | R8: DA3899XS | S8: 12506 | T8: Iya | U8: 45782 | V8: 12506 | W8: https://files.armadanusantara.co.id/bukti/9eb4560249c3.jpg | X8: https://files.armadanusantara.co.id/bukti/a54dc485e7be.png | Y8: PICK UP TRAGA 2.5 4X2 MT D M/T | Z8: KB3403JE | AA8: 62601 | AB8: Iya | AC8: 45782 | AD8: 62601 | AE8: https://files.armadanusantara.co.id/bukti/e69675f2755f.pdf | AF8: https://files.armadanusantara.co.id/bukti/d54361ed1b00.jpeg
A9: 8 | B9: 45859.686 | C9: 45859.699 | D9: 14791@armadanusantara.co.id | E9: Dimas Lubis | G9: 14599 MATARAM | H9: 2 | Q9: Daihatsu Xenia (Badan) | R9: B9347LJ | S9: 46253 | T9: Iya | U9: 45685 | V9: 46253 | W9: https://files.armadanusantara.co.id/bukti/f45617881544.jpg | X9: https://files.armadanusantara.co.id/bukti/6af75781bdb6.jpg | Y9: PICK UP TRAGA 2.5 4X2 MT D M/T | Z9: B4196MS | AA9: 17414 | AB9: Iya | AC9: 45568 | AD9: 17414 | AE9: https://files.armadanusantara.co.id/bukti/cb72298a29ab.png | AF9: https://files.armadanusantara.co.id/bukti/b1180d111352.png
A10: 9 | B10: 45859.698 | C10: 45859.7 | D10: 57650@armadanusantara.co.id | E10: Agus Maulana | G10: 63557 PONTIANAK | H10: 1 | Y10: DAIHATSU GRANMAX PU AC PS 1.5 M/T | Z10: B1229TQ | AA10: 15190 | AB10: Iya | AC10: 45768 | AD10: 15190 | AE10: https://files.armadanusantara.co.id/bukti/c41255a4241c.jpg | AF10: https://files.armadanusantara.co.id/bukti/5c274cb753a2.pdf
A11: 10 | B11: 45859.693 | C11: 45859.703 | D11: 44278@armadanusantara.co.id | E11: Dinda Harahap | G11: 26773 RAHA POS | H11: 1 | Y11: DAIHATSU GRANMAX PU AC PS 1.5 M/T | Z11: B8132XW | AA11: 33133 | AB11: Iya | AC11: 45731 | AD11: 33133 | AE11: https://files.armadanusantara.co.id/bukti/45529312ec27.jpeg | AF11: https://files.armadanusantara.co.id/bukti/0afc665d91c2.jpg
A12: 11 | B12: 45859.695 | C12: 45859.709 | D12: 66284@armadanusantara.co.id | E12: Ratna Pratama | G12: 81258 JAKARTA SELATAN | H12: 1 | Y12: DAIHATSU GRANMAX PU AC PS 1.5 M/T | Z12: KT2986WG | AA12: 3539 | AB12: Iya | AC12: 45841 | AD12: 3539 | AE12: https://files.armadanusantara.co.id/bukti/97a356d063ba.jpg | AF12: https://files.armadanusantara.co.id/bukti/e4bac0cb0c07.png
A13: 12 | B13: 45859.706 | C13: 45859.709 | D13: 45424@armadanusantara.co.id | E13: Joko Darmadi | G13: 43676 DEPOK BRANCH | H13: 1 | Y13: PICK UP TRAGA 2.5 4X2 MT D M/T | Z13: B9006FL | AA13: 17950 | AB13: Iya | AC13: 45755 | AD13: 17950 | AE13: https://files.armadanusantara.co.id/bukti/68f0108c1f45.jpeg | AF13: https://files.armadanusantara.co.id/bukti/09b9ccdac79c.jpg
A14: 13 | B14: 45859.704 | C14: 45859.711 | D14: 94839@armadanusantara.co.id | E14: Intan Simatupang | G14: 51793 LOMBOK BARAT UNIT | H14: 1 | Y14: DAIHATSU GRANMAX PU AC PS 1.5 M/T | Z14: B1377MKN | AA14: 50 | AB14: Iya | AC14: 45762 | AD14: 50 | AE14: https://files.armadanusantara.co.id/bukti/f72cdda35657.png | AF14: https://files.armadanusantara.co.id/bukti/2509ac79e475.pdf
A15: 14 | B15: 45859.706 | C15: 45859.714 | D15: 62138@armadanusantara.co.id | E15: Zahra Waluyo | G15: 28292 WONOGIRI POS | H15: 1 | Y15: PICK UP TRAGA 2.5 4X2 MT D M/T | Z15: B6987KLG | AA15: 37904 | AB15: Iya | AC15: 45821 | AD15: 37904 | AE15: https://files.armadanusantara.co.id/bukti/39e0dc7a20da.pdf | AF15: https://files.armadanusantara.co.id/bukti/6bd71b7d06cf.jpeg
A16: 15 | B16: 45859.709 | C16: 45859.716 | D16: 59473@armadanusantara.co.id | E16: Mahendra Lubis | G16: 24204 TIMIKA | H16: 1 | Y16: PICK UP TRAGA 2.5 4X2 MT D M/T | Z16: B9410TZ | AA16: 13870 | AB16: Iya | AC16: 45765 | AD16: 13870 | AE16: https://files.armadanusantara.co.id/bukti/a94fe30b93dc.png | AF16: https://files.armadanusantara.co.id/bukti/3db4042fb296.pdf
A17: 16 | B17: 45859.694 | C17: 45859.718 | D17: 42105@armadanusantara.co.id | E17: Hadi Efendi | G17: 37568 BANJAR | H17: 2 | Q17: Daihatsu Xenia (Badan) | R17: B8137WEW | S17: 32255 | T17: Iya | U17: 45825 | V17: 32255 | W17: https://files.armadanusantara.co.id/bukti/e1cae3e97b13.png | X17: https://files.armadanusantara.co.id/bukti/b6b2e36f6f09.pdf | Y17: DAIHATSU GRANMAX PU AC PS 1.5 M/T | Z17: B9442MAL | AA17: 16400 | AB17: Iya | AC17: 45825 | AD17: 16400 | AE17: https://files.armadanusantara.co.id/bukti/7e6f4ec80652.jpeg | AF17: https://files.armadanusantara.co.id/bukti/676768ad5586.pdf
A18: 17 | B18: 45859.718 | C18: 45859.727 | D18: 31371@armadanusantara.co.id | E18: Nadia Hutabarat | G18: 17822 BANDUNG | H18: 2 | Q18: Daihatsu Xenia (Badan) | R18: B3590QLB | S18: 15305 | T18: Iya | U18: 45771 | V18: 15305 | W18: https://files.armadanusantara.co.id/bukti/2f1ef9294e62.jpg | X18: https://files.armadanusantara.co.id/bukti/d685295c60b4.pdf | Y18: DAIHATSU GRANMAX PU AC PS 1.5 M/T | Z18: B4001FJ | AA18: 3498 | AB18: Iya | AC18: 45792 | AD18: 3498 | AE18: https://files.armadanusantara.co.id/bukti/a526204ca72a.png | AF18: https://files.armadanusantara.co.id/bukti/8e6da00f2af8.jpg
A19: 18 | B19: 45859.723 | C19: 45859.727 | D19: 35326@armadanusantara.co.id | E19: Guntur Mahendra | G19: 96224 LHOKSEUMAWE | H19: 1 | Y19: DAIHATSU GRANMAX PU AC PS 1.5 M/T | Z19: B9274GSS | AA19: 35706 | AB19: Iya | AC19: 45820 | AD19: 35706 | AE19: https://files.armadanusantara.co.id/bukti/f955d538792d.jpeg | AF19: https://files.armadanusantara.co.id/bukti/f365861e77aa.png
A20: 19 | B20: 45859.716 | C20: 45859.727 | D20: 46129@armadanusantara.co.id | E20: Rani Simatupang | G20: 44007 BANDA ACEH | H20: 1 | Y20: DAIHATSU GRANMAX PU AC PS 1.5 M/T | Z20: B1960LKY | AA20: 45117 | AB20: Iya | AC20: 45762 | AD20: 45117 | AE20: https://files.armadanusantara.co.id/bukti/5335dceaeab2.pdf | AF20: https://files.armadanusantara.co.id/bukti/550fb612ef72.pdf
A21: 20 | B21: 45859.696 | C21: 45859.729 | D21: 47770@armadanusantara.co.id | E21: Sigit Handoko | G21: 92412 MALANG POS | H21: 1 | Y21: DAIHATSU GRANMAX PU AC PS 1.5 M/T | Z21: D8668TS | AA21: 7838 | AB21: Iya | AC21: 45794 | AD21: 7838 | AE21: https://files.armadanusantara.co.id/bukti/01f7a0034f20.jpeg | AF21: https://files.armadanusantara.co.id/bukti/02f4b482d6ef.jpg
A22: 21 | B22: 45859.726 | C22: 45859.733 | D22: 86051@armadanusantara.co.id | E22: Novi Baskoro | G22: 89414 PANGKAL PINANG POS | H22: 1 | Y22: DAIHATSU GRANMAX PU AC PS 1.5 M/T | Z22: B5795ED | AA22: 45142 | AB22: Iya | AC22: 45708 | AD22: 45142 | AE22: https://files.armadanusantara.co.id/bukti/be3b8b8839db.pdf | AF22: https://files.armadanusantara.co.id/bukti/6c710568b330.jpeg
A23: 22 | B23: 45859.736 | C23: 45859.74 | D23: 22045@armadanusantara.co.id | E23: Zaki Utomo | G23: 54229 SRAGEN BRANCH | H23: 1 | Y23: PICK UP TRAGA 2.5 4X2 MT D M/T | Z23: B3050XRL | AA23: 64126 | AB23: Iya | AC23: 45831 | AD23: 64126 | AE23: https://files.armadanusantara.co.id/bukti/b9458ec9f058.pdf | AF23: https://files.armadanusantara.co.id/bukti/60ebe80e65c0.pdf
A24: 23 | B24: 45859.732 | C24: 45859.748 | D24: 21206@armadanusantara.co.id | E24: Indah Situmorang | G24: 82123 SINJAI | H24: 3 | I24: Daihatsu Xenia (Badan) | J24: D9393MC | K24: 53303 | L24: Iya | M24: 45821 | N24: 53303 | O24: https://files.armadanusantara.co.id/bukti/371a46753979.jpeg | P24: https://files.armadanusantara.co.id/bukti/8744446852d8.jpeg | Q24: DAIHATSU GRANMAX PU AC PS 1.5 M/T | R24: B8895WT | S24: 1176 | T24: Iya | U24: 45792 | V24: 1176 | W24: https://files.armadanusantara.co.id/bukti/970c58c785cb.png | X24: https://files.armadanusantara.co.id/bukti/f9eac42c55d7.jpeg | Y24: DAIHATSU GRANMAX PU AC PS 1.5 M/T | Z24: B2840UE | AA24: 79909 | AB24: Iya | AC24: 45856 | AD24: 79909 | AE24: https://files.armadanusantara.co.id/bukti/3ba9a93bd8c8.jpeg | AF24: https://files.armadanusantara.co.id/bukti/555959b23058.jpg
A25: 24 | B25: 45859.742 | C25: 45859.748 | D25: 15433@armadanusantara.co.id | E25: Budi Handoko | G25: 98337 BIMA POS | H25: 1 | Y25: DAIHATSU GRANMAX PU AC PS 1.5 M/T | Z25: B8385EAN | AA25: 14233 | AB25: Iya | AC25: 45783 | AD25: 14233 | AE25: https://files.armadanusantara.co.id/bukti/7a75717e8902.pdf | AF25: https://files.armadanusantara.co.id/bukti/bb5718021bbe.png
A26: 25 | B26: 45859.743 | C26: 45859.756 | D26: 70076@armadanusantara.co.id | E26: Dani Firmansyah | G26: 99918 KAYU AGUNG UNIT | H26: 1 | Y26: PICK UP TRAGA 2.5 4X2 MT D M/T | Z26: B8491EZ | AA26: 13855 | AB26: Iya | AC26: 45812 | AD26: 13855 | AE26: https://files.armadanusantara.co.id/bukti/76c76e7ec592.jpeg | AF26: https://files.armadanusantara.co.id/bukti/a0d98cb1733a.png
A27: 26 | B27: 45859.748 | C27: 45859.761 | D27: 66077@armadanusantara.co.id | E27: Farid Utomo | G27: 71786 TANJUNG PINANG BRANCH | H27: 1 | Y27: DAIHATSU GRANMAX PU AC PS 1.5 M/T | Z27: B1444CKJ | AA27: 79798 | AB27: Iya | AC27: 45805 | AD27: 79798 | AE27: https://files.armadanusantara.co.id/bukti/e8b874630752.pdf | AF27: https://files.armadanusantara.co.id/bukti/d96678784880.jpeg
A28: 27 | B28: 45859.777 | C28: 45859.779 | D28: 47341@armadanusantara.co.id | E28: Wahyu Waluyo | G28: 15893 MAJALENGKA | H28: 1 | Y28: DAIHATSU GRANMAX PU AC PS 1.5 M/T | Z28: B7692UCT | AA28: 6174 | AB28: Iya | AC28: 45827 | AD28: 6174 | AE28: https://files.armadanusantara.co.id/bukti/b2fca95308e2.jpg | AF28: https://files.armadanusantara.co.id/bukti/bb2245920c92.pdf
A29: 28 | B29: 45859.782 | C29: 45859.79 | D29: 60085@armadanusantara.co.id | E29: Indra Suryana | G29: 94865 KARANGANYAR POS | H29: 1 | Y29: DAIHATSU GRANMAX PU AC PS 1.5 M/T | Z29: B8457UZ | AA29: 6917 | AB29: Iya | AC29: 45743 | AD29: 6917 | AE29: https://files.armadanusantara.co.id/bukti/0c55e0426a0e.pdf | AF29: https://files.armadanusantara.co.id/bukti/c32b712235dc.jpeg
A30: 29 | B30: 45859.788 | C30: 45859.792 | D30: 11104@armadanusantara.co.id | E30: Ari Tampubolon | G30: 47339 BENGKULU | H30: 1 | Y30: DAIHATSU GRANMAX PU AC PS 1.5 M/T | Z30: B6236MZW | AA30: 33312 | AB30: Iya | AC30: 45713 | AD30: 33312 | AE30: https://files.armadanusantara.co.id/bukti/d7a947e08a7f.pdf | AF30: https://files.armadanusantara.co.id/bukti/764e669f5da1.png
A31: 30 | B31: 45859.826 | C31: 45859.83 | D31: 89394@armadanusantara.co.id | E31: Yusuf Sihombing | G31: 75534 SAMBAS BRANCH | H31: 1 | Y31: PICK UP TRAGA 2.5 4X2 MT D M/T | Z31: B6013WGR | AA31: 35052 | AB31: Iya | AC31: 45861 | AD31: 35052 | AE31: https://files.armadanusantara.co.id/bukti/94ae6f439546.pdf | AF31: https://files.armadanusantara.co.id/bukti/ffa7d64a524e.pdf
A32: 31 | B32: 45859.832 | C32: 45859.835 | D32: 11780@armadanusantara.co.id | E32: Nur Suryana | G32: 51924 BIAK | H32: 2 | Q32: DAIHATSU GRANMAX PU AC PS 1.5 M/T | R32: B9529CGF | S32: 16620 | T32: Iya | U32: 45736 | V32: 16620 | W32: https://files.armadanusantara.co.id/bukti/fa9f8320e404.jpeg | X32: https://files.armadanusantara.co.id/bukti/e85a90c38efd.pdf | Y32: Daihatsu Xenia (Badan) | Z32: DA9877GL | AA32: 24252 | AB32: Iya | AC32: 45735 | AD32: 24252 | AE32: https://files.armadanusantara.co.id/bukti/5ba88c243f43.pdf | AF32: https://files.armadanusantara.co.id/bukti/6c7fa551bb55.jpeg
A33: 32 | B33: 45859.855 | C33: 45859.861 | D33: 99119@armadanusantara.co.id | E33: Ilham Mahendra | G33: 79735 BANDAR JAYA BRANCH | H33: 1 | Y33: DAIHATSU GRANMAX PU AC PS 1.5 M/T | Z33: B1190TVJ | AA33: 47106 | AB33: Iya | AC33: 45833 | AD33: 47106 | AE33: https://files.armadanusantara.co.id/bukti/cd80d18e44fc.jpeg | AF33: https://files.armadanusantara.co.id/bukti/5ba6a4104ea5.jpeg
A34: 33 | B34: 45860.309 | C34: 45860.309 | D34: 21884@armadanusantara.co.id | E34: Septian Saputra | G34: 38989 PATI | H34: 1 | Y34: PICK UP TRAGA 2.5 4X2 MT D M/T | Z34: B9848XJ | AA34: 67509 | AB34: Iya | AC34: 45997 | AD34: 67509 | AE34: https://files.armadanusantara.co.id/bukti/8458902ad7fa.jpeg | AF34: https://files.armadanusantara.co.id/bukti/859b34efc5bd.jpg
A35: 34 | B35: 45860.304 | C35: 45860.318 | D35: 21162@armadanusantara.co.id | E35: Dimas Adiputra | G35: 84357 BENGKALIS UNIT | H35: 2 | Q35: PICK UP TRAGA 2.5 4X2 MT D M/T | R35: B9897TAZ | S35: 26950 | T35: Iya | U35: 45845 | V35: 26950 | W35: https://files.armadanusantara.co.id/bukti/393593213919.pdf | X35: https://files.armadanusantara.co.id/bukti/d2c0b4f90bc1.png | Y35: DAIHATSU GRANMAX PU AC PS 1.5 M/T | Z35: B8645QN | AA35: 42358 | AB35: Iya | AC35: 45771 | AD35: 42358 | AE35: https://files.armadanusantara.co.id/bukti/6831e9366a29.png | AF35: https://files.armadanusantara.co.id/bukti/2a339840370b.pdf
A36: 35 | B36: 45860.299 | C36: 45860.319 | D36: 57557@armadanusantara.co.id | E36: Bambang Permana | G36: 31340 SEMARANG | H36: 1 | Y36: PICK UP TRAGA 2.5 4X2 MT D M/T | Z36: B1075RA | AA36: 48591 | AB36: Iya | AC36: 45726 | AD36: 48591 | AE36: https://files.armadanusantara.co.id/bukti/2c36c340e2bc.jpeg | AF36: https://files.armadanusantara.co.id/bukti/8ce43ffed7dc.pdf
A37: 36 | B37: 45860.318 | C37: 45860.321 | D37: 94975@armadanusantara.co.id | E37: Yudi Utomo | G37: 46643 SINGKAWANG | H37: 1 | Y37: PICK UP TRAGA 2.5 4X2 MT D M/T | Z37: B2118PQK | AA37: 45753 | AB37: Iya | AC37: 45901 | AD37: 45753 | AE37: https://files.armadanusantara.co.id/bukti/a5d8453ccd65.png | AF37: https://files.armadanusantara.co.id/bukti/d0c6de3e75b9.png
A38: 37 | B38: 45860.318 | C38: 45860.323 | D38: 35309@armadanusantara.co.id | E38: Dwi Winata | G38: 34328 KAMPAR | H38: 2 | Q38: DAIHATSU GRANMAX PU AC PS 1.5 M/T | R38: B7154RP | S38: 47281 | T38: Iya | U38: 45752 | V38: 47281 | W38: https://files.armadanusantara.co.id/bukti/e7e87e8e99f8.jpeg | X38: https://files.armadanusantara.co.id/bukti/fac39515755d.jpg | Y38: PICK UP TRAGA 2.5 4X2 MT D M/T | Z38: B7875XVS | AA38: 15547 | AB38: Iya | AC38: 45812 | AD38: 15547 | AE38: https://files.armadanusantara.co.id/bukti/c3bf132c9698.jpeg | AF38: https://files.armadanusantara.co.id/bukti/94bb41cd175f.png
A39: 38 | B39: 45860.323 | C39: 45860.325 | D39: 82127@armadanusantara.co.id | E39: Hendra Siregar | G39: 48634 PAYAKUMBUH UNIT | H39: 1 | Y39: DAIHATSU GRANMAX PU AC PS 1.5 M/T | Z39: B9910CL | AA39: 3036 | AB39: Iya | AC39: 45776 | AD39: 3036 | AE39: https://files.armadanusantara.co.id/bukti/93f06cab2f8d.pdf | AF39: https://files.armadanusantara.co.id/bukti/b45cf74815be.png
A40: 39 | B40: 45860.328 | C40: 45860.331 | D40: 23723@armadanusantara.co.id | E40: Sari Zulkarnain | G40: 58804 BOYOLALI | H40: 1 | Y40: DAIHATSU GRANMAX PU AC PS 1.5 M/T | Z40: B7351RH | AA40: 50381 | AB40: Iya | AC40: 45668 | AD40: 50381 | AE40: https://files.armadanusantara.co.id/bukti/86a86116822e.jpg | AF40: https://files.armadanusantara.co.id/bukti/ccb89aaa9107.pdf
...

Sheet raw_stack
A1: No | B1: Tanggal Input | C1: Tipe Kendaraan | D1: Nopol | E1: KM Berjalan | F1: Apakah Servis? | G1: Tanggal Servis | H1: KM Servis
A2: {=_xlfn.SEQUENCE(COUNTA(B2:B99411))} -> 1 | B2: {=_xlfn.VSTACK( _xlfn.HSTACK( _xlfn._xlws.FILTER(RAW[Completion time], RAW[Nopol1]<>""), _xlfn._xlws.FILTER(RAW[Tipe Kendaraan1], RAW[Nopol1]<>""), _xlfn._xlws.FILTER(RAW[Nopol1], RAW[Nopol1]<>""), VALUE(_xlfn._xlws.FILTER(RAW[KM Berjalan1], RAW[Nopol1]<>"")), _xlfn._xlws.FILTER(RAW[Apakah Servis?1], RAW[Nopol1]<>""), _xlfn._xlws.FILTER(RAW[Tanggal Service1], RAW[Nopol1]<>""), VALUE(_xlfn._xlws.FILTER(RAW[KM Servis1], RAW[Nopol1]<>"")) ), _xlfn.HSTACK( _xlfn._xlws.FILTER(RAW[Completion time], RAW[Nopol2]<>""), _xlfn._xlws.FILTER(RAW[Tipe Kendaraan2], RAW[Nopol2]<>""), _xlfn._xlws.FILTER(RAW[Nopol2], RAW[Nopol2]<>""), VALUE(_xlfn._xlws.FILTER(RAW[KM Berjalan2], RAW[Nopol2]<>"")), _xlfn._xlws.FILTER(RAW[Apakah Servis?2], RAW[Nopol2]<>""), _xlfn._xlws.FILTER(RAW[Tanggal Service2], RAW[Nopol2]<>""), VALUE(_xlfn._xlws.FILTER(RAW[KM Servis2], RAW[Nopol2]<>"")) ), _xlfn.HSTACK( _xlfn._xlws.FILTER(RAW[Completion time], RAW[Nopol3]<>""), _xlfn._xlws.FILTER(RAW[Tipe Kendaraan3], RAW[Nopol3]<>""), _xlfn._xlws.FILTER(RAW[Nopol3], RAW[Nopol3]<>""), VALUE(_xlfn._xlws.FILTER(RAW[KM Berjalan3], RAW[Nopol3]<>"")), _xlfn._xlws.FILTER(RAW[Apakah Servis?3], RAW[Nopol3]<>""), _xlfn._xlws.FILTER(RAW[Tanggal Service3], RAW[Nopol3]<>""), VALUE(_xlfn._xlws.FILTER(RAW[KM Servis3], RAW[Nopol3]<>"")) ) )} -> 45859.748 | C2: Daihatsu Xenia (Badan) | D2: D9393MC | E2: 53303 | F2: Iya | G2: 45821 | H2: 53303
A3: 2 | B3: 45860.562 | C3: DAIHATSU GRANMAX PU AC PS 1.5 M/T | D3: B3271BYK | E3: 28976 | F3: Iya | G3: 45764 | H3: 28976
A4: 3 | B4: 45860.574 | C4: Daihatsu Xenia (Badan) | D4: B2034KCH | E4: 99715 | F4: Iya | G4: 45808 | H4: 99715
A5: 4 | B5: 45861.696 | C5: PICK UP TRAGA 2.5 4X2 MT D M/T | D5: B5783FB | E5: 14369 | F5: Iya | G5: 45804 | H5: 14369
A6: 5 | B6: 45865.593 | C6: PICK UP TRAGA 2.5 4X2 MT D M/T | D6: L6517DP | E6: 20785 | F6: Iya | G6: 45779 | H6: 20785
A7: 6 | B7: 45867.605 | C7: Daihatsu Xenia (Badan) | D7: B6680XJ | E7: 23257 | F7: Iya | G7: 45822 | H7: 23257
A8: 7 | B8: 45869.828 | C8: PICK UP TRAGA 2.5 4X2 MT D M/T | D8: B8699GN | E8: 61543 | F8: Iya | G8: 45726 | H8: 61543
A9: 8 | B9: 45890.665 | C9: PICK UP TRAGA 2.5 4X2 MT D M/T | D9: B4985JZY | E9: 31499 | F9: Iya | G9: 45881 | H9: 31499
A10: 9 | B10: 45891.373 | C10: Daihatsu Xenia (Badan) | D10: B2034KCH | E10: 99985 | F10: Iya | G10: 45808 | H10: 99985
A11: 10 | B11: 45891.69 | C11: Daihatsu Xenia (Badan) | D11: D9393MC | E11: 56705 | F11: Iya | G11: 45792 | H11: 56705
A12: 11 | B12: 45891.787 | C12: Daihatsu Xenia (Badan) | D12: B2888ALH | E12: 102761 | F12: Iya | G12: 45761 | H12: 102761
A13: 12 | B13: 45892.511 | C13: DAIHATSU GRANMAX PU AC PS 1.5 M/T | D13: AB8086XV | E13: 3219 | F13: Iya | G13: 45783 | H13: 3219
A14: 13 | B14: 45894.72 | C14: Daihatsu Xenia (Badan) | D14: H8376YB | E14: 43361 | F14: Iya | G14: 45829 | H14: 43361
... A2292: 2291 | B2292: 46134.48 | C2292: DAIHATSU GRANMAX PU AC PS 1.5 M/T | D2292: B5151RYU | E2292: 7007 | F2292: Tidak | G2292: 0 | H2292: 0

Sheet filter_per_bulan
A1: FILTER DATA SERVIS KENDARAAN BERDASARKAN BULAN & TAHUN
A2: No | B2: Tanggal Input | C2: Tipe Kendaraan | D2: Nopol | E2: KM Berjalan | F2: Apakah Servis? | G2: Tanggal Servis | H2: KM Servis | I2: Ada/Tidak di Master
A3: {=_xlfn._xlws.FILTER( _xlfn.HSTACK( raw_stack!A2:H100000, IF( COUNTIF(data_master!G:G, raw_stack!D2:D100000)=0, "TIDAK ADA", "ADA" ) ), (MONTH(raw_stack!B2:B100000)=MATCH(M6,{"Januari";"Februari";"Maret";"April";"Mei";"Juni";"Juli";"Agustus";"September";"Oktober";"November";"Desember"},0))* (YEAR(raw_stack!B2:B100000)=M8) )} -> 539 | B3: 46084.509 | C3: Daihatsu Xenia (Badan) | D3: B6817ZM | E3: 16143 | F3: Iya | G3: 45972 | H3: 16143 | I3: ADA
A4: 540 | B4: 46084.61 | C4: Daihatsu Xenia (Badan) | D4: B3797RA | E4: 21361 | F4: Iya | G4: 46059 | H4: 21361 | I4: ADA
A5: 541 | B5: 46084.669 | C5: DAIHATSU GRANMAX PU AC PS 1.5 M/T | D5: B8457UZ | E5: 18313 | F5: Iya | G5: 46056 | H5: 18313 | I5: ADA
A6: 542 | B6: 46084.674 | C6: PICK UP TRAGA 2.5 4X2 MT D M/T | D6: B1444ZS | E6: 5257 | F6: Iya | G6: 45999 | H6: 5257 | I6: ADA | K6: BULAN: | M6: Maret
A7: 543 | B7: 46084.68 | C7: PICK UP TRAGA 2.5 4X2 MT D M/T | D7: KB3403JE | E7: 79223 | F7: Iya | G7: 46063 | H7: 79223 | I7: TIDAK ADA
A8: 544 | B8: 46084.681 | C8: DAIHATSU GRANMAX PU AC PS 1.5 M/T | D8: KT2986WG | E8: 55976 | F8: Iya | G8: 45958 | H8: 55976 | I8: ADA | K8: TAHUN: | M8: 2026
A9: 545 | B9: 46085.34 | C9: Daihatsu Xenia (Badan) | D9: B8054VY | E9: 22972 | F9: Iya | G9: 45923 | H9: 22972 | I9: ADA
A10: 546 | B10: 46085.365 | C10: Daihatsu Xenia (Badan) | D10: B2306NS | E10: 34381 | F10: Iya | G10: 45985 | H10: 34381 | I10: ADA
A11: 547 | B11: 46085.405 | C11: Daihatsu Xenia (Badan) | D11: B6851IH | E11: 14457 | F11: Iya | G11: 46044 | H11: 14457 | I11: ADA
A12: 548 | B12: 46085.408 | C12: Daihatsu Xenia (Badan) | D12: B8763MP | E12: 97373 | F12: Iya | G12: 46029 | H12: 97373 | I12: ADA
A13: 549 | B13: 46085.46 | C13: Daihatsu Xenia (Badan) | D13: B8430ECN | E13: 1894 | F13: Iya | G13: 46085 | H13: 1894 | I13: ADA
A14: 550 | B14: 46085.476 | C14: Daihatsu Xenia (Badan) | D14: B8137WEW | E14: 40287 | F14: Iya | G14: 46000 | H14: 40287 | I14: ADA
A15: 551 | B15: 46085.66 | C15: Daihatsu Xenia (Badan) | D15: B9619FMM | E15: 76041 | F15: Iya | G15: 45937 | H15: 76041 | I15: TIDAK ADA
A16: 552 | B16: 46085.677 | C16: Daihatsu Xenia (Badan) | D16: B2823MF | E16: 28946 | F16: Iya | G16: 45978 | H16: 28946 | I16: ADA
A17: 553 | B17: 46085.698 | C17: Daihatsu Xenia (Badan) | D17: B2888ALH | E17: 114050 | F17: Iya | G17: 45953 | H17: 114050 | I17: TIDAK ADA
A18: 554 | B18: 46086.361 | C18: DAIHATSU GRANMAX PU AC PS 1.5 M/T | D18: B5518KS | E18: 2765 | F18: Iya | G18: 45967 | H18: 2765 | I18: ADA
A19: 555 | B19: 46086.377 | C19: Daihatsu Xenia (Badan) | D19: B8324WSJ | E19: 20057 | F19: Iya | G19: 46063 | H19: 20057 | I19: ADA
A20: 556 | B20: 46086.503 | C20: DAIHATSU GRANMAX PU AC PS 1.5 M/T | D20: B7326IW | E20: 31724 | F20: Iya | G20: 46079 | H20: 31724 | I20: ADA
... A226: 2196 | B226: 46112.731 | C226: DAIHATSU GRANMAX PU AC PS 1.5 M/T | D226: KB9985GGA | E226: 17887 | F226: Iya | G226: 45937 | H226: 17887 | I226: ADA

Sheet data_anomali
A1: DATA ANOMALI
A2: No | B2: Tanggal Input | C2: Tipe Kendaraan | D2: Nopol | E2: KM Berjalan | F2: Apakah Servis? | G2: Tanggal Servis | H2: KM Servis | I2: Keterangan
A3: {=_xlfn._xlws.FILTER( _xlfn.HSTACK( raw_stack!A2:H100000, IF( (raw_stack!D2:D100000<>"") * ( (raw_stack!G2:G100000>TODAY()) + (IFERROR(raw_stack!E2:E100000,0) < IFERROR(raw_stack!H2:H100000,0)) + (NOT(ISNUMBER(raw_stack!E2:E100000))) + (NOT(ISNUMBER(raw_stack!H2:H100000))) ), IF(raw_stack!G2:G100000>TODAY(), "Tanggal > Hari Ini", "") & IF( (raw_stack!G2:G100000>TODAY()) * ((IFERROR(raw_stack!E2:E100000,0) < IFERROR(raw_stack!H2:H100000,0))), ", ", "" ) & IF(IFERROR(raw_stack!E2:E100000,0) < IFERROR(raw_stack!H2:H100000,0), "Selisih KM Minus", "") & IF( NOT(ISNUMBER(raw_stack!E2:E100000)), ", KM Berjalan Bukan Angka", "" ) & IF( NOT(ISNUMBER(raw_stack!H2:H100000)), ", KM Servis Bukan Angka", "" ), "" ) ), (raw_stack!D2:D100000<>"") * ( (raw_stack!G2:G100000>TODAY()) + (IFERROR(raw_stack!E2:E100000,0) < IFERROR(raw_stack!H2:H100000,0)) + (NOT(ISNUMBER(raw_stack!E2:E100000))) + (NOT(ISNUMBER(raw_stack!H2:H100000))) ) )} -> 519 | B3: 46045.483 | C3: Daihatsu Xenia (Badan) | D3: B9558JSZ | E3: 21574 | F3: Iya | G3: 46374 | H3: 21574 | I3: Tanggal > Hari Ini
A4: 594 | B4: 46129.561 | C4: DAIHATSU GRANMAX PU AC PS 1.5 M/T | D4: B1042EB | E4: 3965 | F4: Iya | G4: 46099 | H4: 14407 | I4: Selisih KM Minus
A5: 2032 | B5: 46084.545 | C5: DAIHATSU GRANMAX PU AC PS 1.5 M/T | D5: B1960LKY | E5: 49627 | F5: Iya | G5: 46296 | H5: 49627 | I5: Tanggal > Hari Ini
A6: 2125 | B6: 46091.712 | C6: DAIHATSU GRANMAX PU AC PS 1.5 M/T | D6: B6407IG | E6: 2108 | F6: Iya | G6: 46351 | H6: 2108 | I6: Tanggal > Hari Ini
A7: 2199 | B7: 46125.444 | C7: DAIHATSU GRANMAX PU AC PS 1.5 M/T | D7: KT4620NQ | E7: 18603 | F7: Iya | G7: 46093 | H7: 27680 | I7: Selisih KM Minus
A8: 2217 | B8: 46129.451 | C8: DAIHATSU GRANMAX PU AC PS 1.5 M/T | D8: B2639ZDE | E8: 2458 | F8: Iya | G8: 46090 | H8: 16109 | I8: Selisih KM Minus
A9: 2220 | B9: 46129.46 | C9: DAIHATSU GRANMAX PU AC PS 1.5 M/T | D9: B2960MA | E9: 64698 | F9: Iya | G9: 46116 | H9: 65160 | I9: Selisih KM Minus
A10: 2264 | B10: 46130.357 | C10: PICK UP TRAGA 2.5 4X2 MT D M/T | D10: B3889CE | E10: 23686 | F10: Iya | G10: 45937 | H10: 31167 | I10: Selisih KM Minus
A11: 2271 | B11: 46130.784 | C11: DAIHATSU GRANMAX PU AC PS 1.5 M/T | D11: B8474IXR | E11: 22322 | F11: Iya | G11: 46123 | H11: 31121 | I11: Selisih KM Minus

Sheet data_master
A1: NO | B1: KODE | C1: RENTAL TYPE CODE | D1: CABANG | E1: ITEM TYPE | F1: RENTAL TYPE | G1: NO POLISI | H1: PIC | I1: JENIS | J1: UNIT PRICE | K1: RENTAL START DATE | L1: RENTAL END DATE | M1: LAST INVOICED END DATE | N1: STATUS | O1: SERVICE JUL 2025 | P1: KM SERVICE | Q1: SERVICE AUG 2025 | R1: KM SERVICE | S1: SERVICE SEP 2025 | T1: KM SERVICE | U1: SERVICE OKT 2025 | V1: KM SERVICE | W1: SERVICE NOV 2025 | X1: KM SERVICE | Y1: SERVICE DEC 2025 | Z1: KM SERVICE | AA1: SERVICE JAN 2026 | AB1: KM SERVICE | AC1: SERVICE FEB 2026 | AD1: KM SERVICE | AE1: SERVICE MAR 2026 | AF1: KM SERVICE | AG1: SERVICE APR 2026 | AH1: KM SERVICE
A2: 1 | B2: =LEFT(D2,5) -> 48431 | C2: Vehicle Rent | D2: 48431 SAMPANG UNIT | E2: Daihatsu Xenia (Badan) | F2: Sewa kendaraan operasional | G2: B4474RVI | H2: OPR | I2: MINIBUS | J2: 3925000 | K2: 46067 | L2: 46431 | M2: 46066 | N2: ACTIVE | O2: =_xlfn.LET( _xlpm.x, _xlfn.MAXIFS( raw_stack!G$2:G$100000, raw_stack!D$2:D$100000, G2, raw_stack!F$2:F$100000, "Iya", raw_stack!G$2:G$100000, ">="&DATE(2025,7,1), raw_stack!G$2:G$100000, "<="&EOMONTH(DATE(2025,7,1),0) ), IF(_xlpm.x=0, "-", _xlpm.x) ) -> - | P2: =_xlfn.LET( _xlpm.x, _xlfn.MAXIFS( raw_stack!H$2:H$100000, raw_stack!D$2:D$100000, G2, raw_stack!F$2:F$100000, "Iya", raw_stack!G$2:G$100000, ">="&DATE(2025,7,1), raw_stack!G$2:G$100000, "<="&EOMONTH(DATE(2025,7,1),0) ), IF(OR(_xlpm.x=0, _xlpm.x=""), "-", _xlpm.x) ) -> - | Q2: =_xlfn.LET( _xlpm.x, _xlfn.MAXIFS( raw_stack!G$2:G$99411, raw_stack!D$2:D$99411, G2, raw_stack!F$2:F$99411, "Iya", raw_stack!G$2:G$99411, ">="&DATE(2025,8,1), raw_stack!G$2:G$99411, "<="&EOMONTH(DATE(2025,8,1),0) ), IF(_xlpm.x=0, "-", _xlpm.x) ) -> 45897 | R2: =_xlfn.LET( _xlpm.x, _xlfn.MAXIFS( raw_stack!H$2:H$100000, raw_stack!D$2:D$100000, G2, raw_stack!F$2:F$100000, "Iya", raw_stack!G$2:G$100000, ">="&DATE(2025,8,1), raw_stack!G$2:G$100000, "<="&EOMONTH(DATE(2025,8,1),0) ), IF(OR(_xlpm.x=0, _xlpm.x=""), "-", _xlpm.x) ) -> 68652 | S2: =_xlfn.LET( _xlpm.x, _xlfn.MAXIFS( raw_stack!G$2:G$99411, raw_stack!D$2:D$99411, G2, raw_stack!F$2:F$99411, "Iya", raw_stack!G$2:G$99411, ">="&DATE(2025,9,1), raw_stack!G$2:G$99411, "<="&EOMONTH(DATE(2025,9,1),0) ), IF(_xlpm.x=0, "-", _xlpm.x) ) -> - | T2: =_xlfn.LET( _xlpm.x, _xlfn.MAXIFS( raw_stack!H$2:H$100000, raw_stack!D$2:D$100000, G2, raw_stack!F$2:F$100000, "Iya", raw_stack!G$2:G$100000, ">="&DATE(2025,9,1), raw_stack!G$2:G$100000, "<="&EOMONTH(DATE(2025,9,1),0) ), IF(OR(_xlpm.x=0, _xlpm.x=""), "-", _xlpm.x) ) -> - | U2: =_xlfn.LET( _xlpm.x, _xlfn.MAXIFS( raw_stack!G$2:G$99411, raw_stack!D$2:D$99411, G2, raw_stack!F$2:F$99411, "Iya", raw_stack!G$2:G$99411, ">="&DATE(2025,10,1), raw_stack!G$2:G$99411, "<="&EOMONTH(DATE(2025,10,1),0) ), IF(_xlpm.x=0, "-", _xlpm.x) ) -> - | V2: =_xlfn.LET( _xlpm.x, _xlfn.MAXIFS( raw_stack!H$2:H$100000, raw_stack!D$2:D$100000, G2, raw_stack!F$2:F$100000, "Iya", raw_stack!G$2:G$100000, ">="&DATE(2025,10,1), raw_stack!G$2:G$100000, "<="&EOMONTH(DATE(2025,10,1),0) ), IF(OR(_xlpm.x=0, _xlpm.x=""), "-", _xlpm.x) ) -> - | W2: =_xlfn.LET( _xlpm.x, _xlfn.MAXIFS( raw_stack!G$2:G$99411, raw_stack!D$2:D$99411, G2, raw_stack!F$2:F$99411, "Iya", raw_stack!G$2:G$99411, ">="&DATE(2025,11,1), raw_stack!G$2:G$99411, "<="&EOMONTH(DATE(2025,11,1),0) ), IF(_xlpm.x=0, "-", _xlpm.x) ) -> - | X2: =_xlfn.LET( _xlpm.x, _xlfn.MAXIFS( raw_stack!H$2:H$100000, raw_stack!D$2:D$100000, G2, raw_stack!F$2:F$100000, "Iya", raw_stack!G$2:G$100000, ">="&DATE(2025,11,1), raw_stack!G$2:G$100000, "<="&EOMONTH(DATE(2025,11,1),0) ), IF(OR(_xlpm.x=0, _xlpm.x=""), "-", _xlpm.x) ) -> - | Y2: =_xlfn.LET( _xlpm.x, _xlfn.MAXIFS( raw_stack!G$2:G$99411, raw_stack!D$2:D$99411, G2, raw_stack!F$2:F$99411, "Iya", raw_stack!G$2:G$99411, ">="&DATE(2025,12,1), raw_stack!G$2:G$99411, "<="&EOMONTH(DATE(2025,12,1),0) ), IF(_xlpm.x=0, "-", _xlpm.x) ) -> - | Z2: =_xlfn.LET( _xlpm.x, _xlfn.MAXIFS( raw_stack!H$2:H$100000, raw_stack!D$2:D$100000, G2, raw_stack!F$2:F$100000, "Iya", raw_stack!G$2:G$100000, ">="&DATE(2025,12,1), raw_stack!G$2:G$100000, "<="&EOMONTH(DATE(2025,12,1),0) ), IF(OR(_xlpm.x=0, _xlpm.x=""), "-", _xlpm.x) ) -> - | AA2: =_xlfn.LET( _xlpm.x, _xlfn.MAXIFS( raw_stack!G$2:G$99411, raw_stack!D$2:D$99411, G2, raw_stack!F$2:F$99411, "Iya", raw_stack!G$2:G$99411, ">="&DATE(2026,1,1), raw_stack!G$2:G$99411, "<="&EOMONTH(DATE(2026,1,1),0) ), IF(_xlpm.x=0, "-", _xlpm.x) ) -> - | AB2: =_xlfn.LET( _xlpm.x, _xlfn.MAXIFS( raw_stack!H$2:H$100000, raw_stack!D$2:D$100000, G2, raw_stack!F$2:F$100000, "Iya", raw_stack!G$2:G$100000, ">="&DATE(2026,1,1), raw_stack!G$2:G$100000, "<="&EOMONTH(DATE(2026,1,1),0) ), IF(OR(_xlpm.x=0, _xlpm.x=""), "-", _xlpm.x) ) -> - | AC2: =_xlfn.LET( _xlpm.x, _xlfn.MAXIFS( raw_stack!G$2:G$99411, raw_stack!D$2:D$99411, G2, raw_stack!F$2:F$99411, "Iya", raw_stack!G$2:G$99411, ">="&DATE(2026,2,1), raw_stack!G$2:G$99411, "<="&EOMONTH(DATE(2026,2,1),0) ), IF(_xlpm.x=0, "-", _xlpm.x) ) -> - | AD2: =_xlfn.LET( _xlpm.x, _xlfn.MAXIFS( raw_stack!H$2:H$100000, raw_stack!D$2:D$100000, G2, raw_stack!F$2:F$100000, "Iya", raw_stack!G$2:G$100000, ">="&DATE(2026,2,1), raw_stack!G$2:G$100000, "<="&EOMONTH(DATE(2026,2,1),0) ), IF(OR(_xlpm.x=0, _xlpm.x=""), "-", _xlpm.x) ) -> - | AE2: =_xlfn.LET( _xlpm.x, _xlfn.MAXIFS( raw_stack!G$2:G$100000, raw_stack!D$2:D$100000, G2, raw_stack!F$2:F$100000, "Iya", raw_stack!G$2:G$100000, ">="&DATE(2026,3,1), raw_stack!G$2:G$100000, "<="&EOMONTH(DATE(2026,3,1),0) ), IF(_xlpm.x=0, "-", _xlpm.x) ) -> - | AF2: =_xlfn.LET( _xlpm.x, _xlfn.MAXIFS( raw_stack!H$2:H$100000, raw_stack!D$2:D$100000, G2, raw_stack!F$2:F$100000, "Iya", raw_stack!G$2:G$100000, ">="&DATE(2026,3,1), raw_stack!G$2:G$100000, "<="&EOMONTH(DATE(2026,3,1),0) ), IF(OR(_xlpm.x=0, _xlpm.x=""), "-", _xlpm.x) ) -> - | AG2: =_xlfn.LET( _xlpm.x, _xlfn.MAXIFS( raw_stack!G$2:G$100000, raw_stack!D$2:D$100000, G2, raw_stack!F$2:F$100000, "Iya", raw_stack!G$2:G$100000, ">="&DATE(2026,4,1), raw_stack!G$2:G$100000, "<="&EOMONTH(DATE(2026,4,1),0) ), IF(_xlpm.x=0, "-", _xlpm.x) ) -> - | AH2: =_xlfn.LET( _xlpm.x, _xlfn.MAXIFS( raw_stack!H$2:H$100000, raw_stack!D$2:D$100000, G2, raw_stack!F$2:F$100000, "Iya", raw_stack!G$2:G$100000, ">="&DATE(2026,4,1), raw_stack!G$2:G$100000, "<="&EOMONTH(DATE(2026,4,1),0) ), IF(OR(_xlpm.x=0, _xlpm.x=""), "-", _xlpm.x) ) -> -
A3: 2 | B3: =LEFT(D3,5) -> 69968 | C3: Vehicle Rent | D3: 69968 BALIKPAPAN | E3: Gran Max Pick Up (TRAC) | F3: Sewa kendaraan operasional | G3: B8269XJ | H3: OPR | I3: PICKUP | J3: 3605000 | K3: 46075 | L3: 46255 | M3: 46074 | N3: ACTIVE | O3: =_xlfn.LET( _xlpm.x, _xlfn.MAXIFS( raw_stack!G$2:G$100000, raw_stack!D$2:D$100000, G3, raw_stack!F$2:F$100000, "Iya", raw_stack!G$2:G$100000, ">="&DATE(2025,7,1), raw_stack!G$2:G$100000, "<="&EOMONTH(DATE(2025,7,1),0) ), IF(_xlpm.x=0, "-", _xlpm.x) ) -> - | P3: =_xlfn.LET( _xlpm.x, _xlfn.MAXIFS( raw_stack!H$2:H$100000, raw_stack!D$2:D$100000, G3, raw_stack!F$2:F$100000, "Iya", raw_stack!G$2:G$100000, ">="&DATE(2025,7,1), raw_stack!G$2:G$100000, "<="&EOMONTH(DATE(2025,7,1),0) ), IF(OR(_xlpm.x=0, _xlpm.x=""), "-", _xlpm.x) ) -> - | Q3: =_xlfn.LET( _xlpm.x, _xlfn.MAXIFS( raw_stack!G$2:G$99411, raw_stack!D$2:D$99411, G3, raw_stack!F$2:F$99411, "Iya", raw_stack!G$2:G$99411, ">="&DATE(2025,8,1), raw_stack!G$2:G$99411, "<="&EOMONTH(DATE(2025,8,1),0) ), IF(_xlpm.x=0, "-", _xlpm.x) ) -> - | R3: =_xlfn.LET( _xlpm.x, _xlfn.MAXIFS( raw_stack!H$2:H$100000, raw_stack!D$2:D$100000, G3, raw_stack!F$2:F$100000, "Iya", raw_stack!G$2:G$100000, ">="&DATE(2025,8,1), raw_stack!G$2:G$100000, "<="&EOMONTH(DATE(2025,8,1),0) ), IF(OR(_xlpm.x=0, _xlpm.x=""), "-", _xlpm.x) ) -> - | S3: =_xlfn.LET( _xlpm.x, _xlfn.MAXIFS( raw_stack!G$2:G$99411, raw_stack!D$2:D$99411, G3, raw_stack!F$2:F$99411, "Iya", raw_stack!G$2:G$99411, ">="&DATE(2025,9,1), raw_stack!G$2:G$99411, "<="&EOMONTH(DATE(2025,9,1),0) ), IF(_xlpm.x=0, "-", _xlpm.x) ) -> 45924 | T3: =_xlfn.LET( _xlpm.x, _xlfn.MAXIFS( raw_stack!H$2:H$100000, raw_stack!D$2:D$100000, G3, raw_stack!F$2:F$100000, "Iya", raw_stack!G$2:G$100000, ">="&DATE(2025,9,1), raw_stack!G$2:G$100000, "<="&EOMONTH(DATE(2025,9,1),0) ), IF(OR(_xlpm.x=0, _xlpm.x=""), "-", _xlpm.x) ) -> 26493 | U3: =_xlfn.LET( _xlpm.x, _xlfn.MAXIFS( raw_stack!G$2:G$99411, raw_stack!D$2:D$99411, G3, raw_stack!F$2:F$99411, "Iya", raw_stack!G$2:G$99411, ">="&DATE(2025,10,1), raw_stack!G$2:G$99411, "<="&EOMONTH(DATE(2025,10,1),0) ), IF(_xlpm.x=0, "-", _xlpm.x) ) -> - | V3: =_xlfn.LET( _xlpm.x, _xlfn.MAXIFS( raw_stack!H$2:H$100000, raw_stack!D$2:D$100000, G3, raw_stack!F$2:F$100000, "Iya", raw_stack!G$2:G$100000, ">="&DATE(2025,10,1), raw_stack!G$2:G$100000, "<="&EOMONTH(DATE(2025,10,1),0) ), IF(OR(_xlpm.x=0, _xlpm.x=""), "-", _xlpm.x) ) -> - | W3: =_xlfn.LET( _xlpm.x, _xlfn.MAXIFS( raw_stack!G$2:G$99411, raw_stack!D$2:D$99411, G3, raw_stack!F$2:F$99411, "Iya", raw_stack!G$2:G$99411, ">="&DATE(2025,11,1), raw_stack!G$2:G$99411, "<="&EOMONTH(DATE(2025,11,1),0) ), IF(_xlpm.x=0, "-", _xlpm.x) ) -> - | X3: =_xlfn.LET( _xlpm.x, _xlfn.MAXIFS( raw_stack!H$2:H$100000, raw_stack!D$2:D$100000, G3, raw_stack!F$2:F$100000, "Iya", raw_stack!G$2:G$100000, ">="&DATE(2025,11,1), raw_stack!G$2:G$100000, "<="&EOMONTH(DATE(2025,11,1),0) ), IF(OR(_xlpm.x=0, _xlpm.x=""), "-", _xlpm.x) ) -> - | Y3: =_xlfn.LET( _xlpm.x, _xlfn.MAXIFS( raw_stack!G$2:G$99411, raw_stack!D$2:D$99411, G3, raw_stack!F$2:F$99411, "Iya", raw_stack!G$2:G$99411, ">="&DATE(2025,12,1), raw_stack!G$2:G$99411, "<="&EOMONTH(DATE(2025,12,1),0) ), IF(_xlpm.x=0, "-", _xlpm.x) ) -> - | Z3: =_xlfn.LET( _xlpm.x, _xlfn.MAXIFS( raw_stack!H$2:H$100000, raw_stack!D$2:D$100000, G3, raw_stack!F$2:F$100000, "Iya", raw_stack!G$2:G$100000, ">="&DATE(2025,12,1), raw_stack!G$2:G$100000, "<="&EOMONTH(DATE(2025,12,1),0) ), IF(OR(_xlpm.x=0, _xlpm.x=""), "-", _xlpm.x) ) -> - | AA3: =_xlfn.LET( _xlpm.x, _xlfn.MAXIFS( raw_stack!G$2:G$99411, raw_stack!D$2:D$99411, G3, raw_stack!F$2:F$99411, "Iya", raw_stack!G$2:G$99411, ">="&DATE(2026,1,1), raw_stack!G$2:G$99411, "<="&EOMONTH(DATE(2026,1,1),0) ), IF(_xlpm.x=0, "-", _xlpm.x) ) -> 46036 | AB3: =_xlfn.LET( _xlpm.x, _xlfn.MAXIFS( raw_stack!H$2:H$100000, raw_stack!D$2:D$100000, G3, raw_stack!F$2:F$100000, "Iya", raw_stack!G$2:G$100000, ">="&DATE(2026,1,1), raw_stack!G$2:G$100000, "<="&EOMONTH(DATE(2026,1,1),0) ), IF(OR(_xlpm.x=0, _xlpm.x=""), "-", _xlpm.x) ) -> 31963 | AC3: =_xlfn.LET( _xlpm.x, _xlfn.MAXIFS( raw_stack!G$2:G$99411, raw_stack!D$2:D$99411, G3, raw_stack!F$2:F$99411, "Iya", raw_stack!G$2:G$99411, ">="&DATE(2026,2,1), raw_stack!G$2:G$99411, "<="&EOMONTH(DATE(2026,2,1),0) ), IF(_xlpm.x=0, "-", _xlpm.x) ) -> - | AD3: =_xlfn.LET( _xlpm.x, _xlfn.MAXIFS( raw_stack!H$2:H$100000, raw_stack!D$2:D$100000, G3, raw_stack!F$2:F$100000, "Iya", raw_stack!G$2:G$100000, ">="&DATE(2026,2,1), raw_stack!G$2:G$100000, "<="&EOMONTH(DATE(2026,2,1),0) ), IF(OR(_xlpm.x=0, _xlpm.x=""), "-", _xlpm.x) ) -> - | AE3: =_xlfn.LET( _xlpm.x, _xlfn.MAXIFS( raw_stack!G$2:G$100000, raw_stack!D$2:D$100000, G3, raw_stack!F$2:F$100000, "Iya", raw_stack!G$2:G$100000, ">="&DATE(2026,3,1), raw_stack!G$2:G$100000, "<="&EOMONTH(DATE(2026,3,1),0) ), IF(_xlpm.x=0, "-", _xlpm.x) ) -> - | AF3: =_xlfn.LET( _xlpm.x, _xlfn.MAXIFS( raw_stack!H$2:H$100000, raw_stack!D$2:D$100000, G3, raw_stack!F$2:F$100000, "Iya", raw_stack!G$2:G$100000, ">="&DATE(2026,3,1), raw_stack!G$2:G$100000, "<="&EOMONTH(DATE(2026,3,1),0) ), IF(OR(_xlpm.x=0, _xlpm.x=""), "-", _xlpm.x) ) -> - | AG3: =_xlfn.LET( _xlpm.x, _xlfn.MAXIFS( raw_stack!G$2:G$100000, raw_stack!D$2:D$100000, G3, raw_stack!F$2:F$100000, "Iya", raw_stack!G$2:G$100000, ">="&DATE(2026,4,1), raw_stack!G$2:G$100000, "<="&EOMONTH(DATE(2026,4,1),0) ), IF(_xlpm.x=0, "-", _xlpm.x) ) -> - | AH3: =_xlfn.LET( _xlpm.x, _xlfn.MAXIFS( raw_stack!H$2:H$100000, raw_stack!D$2:D$100000, G3, raw_stack!F$2:F$100000, "Iya", raw_stack!G$2:G$100000, ">="&DATE(2026,4,1), raw_stack!G$2:G$100000, "<="&EOMONTH(DATE(2026,4,1),0) ), IF(OR(_xlpm.x=0, _xlpm.x=""), "-", _xlpm.x) ) -> -
A4: 3 | B4: =LEFT(D4,5) -> 23209 | C4: Vehicle Rent | D4: 23209 SUBANG POS | E4: Gran Max Pick Up (Badan) | F4: Sewa kendaraan operasional | G4: B9912VG | H4: OPR | I4: PICKUP | J4: 5075000 | K4: 46081 | L4: 46261 | M4: 46049 | N4: ACTIVE | O4: =_xlfn.LET( _xlpm.x, _xlfn.MAXIFS( raw_stack!G$2:G$100000, raw_stack!D$2:D$100000, G4, raw_stack!F$2:F$100000, "Iya", raw_stack!G$2:G$100000, ">="&DATE(2025,7,1), raw_stack!G$2:G$100000, "<="&EOMONTH(DATE(2025,7,1),0) ), IF(_xlpm.x=0, "-", _xlpm.x) ) -> - | P4: =_xlfn.LET( _xlpm.x, _xlfn.MAXIFS( raw_stack!H$2:H$100000, raw_stack!D$2:D$100000, G4, raw_stack!F$2:F$100000, "Iya", raw_stack!G$2:G$100000, ">="&DATE(2025,7,1), raw_stack!G$2:G$100000, "<="&EOMONTH(DATE(2025,7,1),0) ), IF(OR(_xlpm.x=0, _xlpm.x=""), "-", _xlpm.x) ) -> - | Q4: =_xlfn.LET( _xlpm.x, _xlfn.MAXIFS( raw_stack!G$2:G$99411, raw_stack!D$2:D$99411, G4, raw_stack!F$2:F$99411, "Iya", raw_stack!G$2:G$99411, ">="&DATE(2025,8,1), raw_stack!G$2:G$99411, "<="&EOMONTH(DATE(2025,8,1),0) ), IF(_xlpm.x=0, "-", _xlpm.x) ) -> - | R4: =_xlfn.LET( _xlpm.x, _xlfn.MAXIFS( raw_stack!H$2:H$100000, raw_stack!D$2:D$100000, G4, raw_stack!F$2:F$100000, "Iya", raw_stack!G$2:G$100000, ">="&DATE(2025,8,1), raw_stack!G$2:G$100000, "<="&EOMONTH(DATE(2025,8,1),0) ), IF(OR(_xlpm.x=0, _xlpm.x=""), "-", _xlpm.x) ) -> - | S4: =_xlfn.LET( _xlpm.x, _xlfn.MAXIFS( raw_stack!G$2:G$99411, raw_stack!D$2:D$99411, G4, raw_stack!F$2:F$99411, "Iya", raw_stack!G$2:G$99411, ">="&DATE(2025,9,1), raw_stack!G$2:G$99411, "<="&EOMONTH(DATE(2025,9,1),0) ), IF(_xlpm.x=0, "-", _xlpm.x) ) -> 45918 | T4: =_xlfn.LET( _xlpm.x, _xlfn.MAXIFS( raw_stack!H$2:H$100000, raw_stack!D$2:D$100000, G4, raw_stack!F$2:F$100000, "Iya", raw_stack!G$2:G$100000, ">="&DATE(2025,9,1), raw_stack!G$2:G$100000, "<="&EOMONTH(DATE(2025,9,1),0) ), IF(OR(_xlpm.x=0, _xlpm.x=""), "-", _xlpm.x) ) -> 115845 | U4: =_xlfn.LET( _xlpm.x, _xlfn.MAXIFS( raw_stack!G$2:G$99411, raw_stack!D$2:D$99411, G4, raw_stack!F$2:F$99411, "Iya", raw_stack!G$2:G$99411, ">="&DATE(2025,10,1), raw_stack!G$2:G$99411, "<="&EOMONTH(DATE(2025,10,1),0) ), IF(_xlpm.x=0, "-", _xlpm.x) ) -> - | V4: =_xlfn.LET( _xlpm.x, _xlfn.MAXIFS( raw_stack!H$2:H$100000, raw_stack!D$2:D$100000, G4, raw_stack!F$2:F$100000, "Iya", raw_stack!G$2:G$100000, ">="&DATE(2025,10,1), raw_stack!G$2:G$100000, "<="&EOMONTH(DATE(2025,10,1),0) ), IF(OR(_xlpm.x=0, _xlpm.x=""), "-", _xlpm.x) ) -> - | W4: =_xlfn.LET( _xlpm.x, _xlfn.MAXIFS( raw_stack!G$2:G$99411, raw_stack!D$2:D$99411, G4, raw_stack!F$2:F$99411, "Iya", raw_stack!G$2:G$99411, ">="&DATE(2025,11,1), raw_stack!G$2:G$99411, "<="&EOMONTH(DATE(2025,11,1),0) ), IF(_xlpm.x=0, "-", _xlpm.x) ) -> - | X4: =_xlfn.LET( _xlpm.x, _xlfn.MAXIFS( raw_stack!H$2:H$100000, raw_stack!D$2:D$100000, G4, raw_stack!F$2:F$100000, "Iya", raw_stack!G$2:G$100000, ">="&DATE(2025,11,1), raw_stack!G$2:G$100000, "<="&EOMONTH(DATE(2025,11,1),0) ), IF(OR(_xlpm.x=0, _xlpm.x=""), "-", _xlpm.x) ) -> - | Y4: =_xlfn.LET( _xlpm.x, _xlfn.MAXIFS( raw_stack!G$2:G$99411, raw_stack!D$2:D$99411, G4, raw_stack!F$2:F$99411, "Iya", raw_stack!G$2:G$99411, ">="&DATE(2025,12,1), raw_stack!G$2:G$99411, "<="&EOMONTH(DATE(2025,12,1),0) ), IF(_xlpm.x=0, "-", _xlpm.x) ) -> - | Z4: =_xlfn.LET( _xlpm.x, _xlfn.MAXIFS( raw_stack!H$2:H$100000, raw_stack!D$2:D$100000, G4, raw_stack!F$2:F$100000, "Iya", raw_stack!G$2:G$100000, ">="&DATE(2025,12,1), raw_stack!G$2:G$100000, "<="&EOMONTH(DATE(2025,12,1),0) ), IF(OR(_xlpm.x=0, _xlpm.x=""), "-", _xlpm.x) ) -> - | AA4: =_xlfn.LET( _xlpm.x, _xlfn.MAXIFS( raw_stack!G$2:G$99411, raw_stack!D$2:D$99411, G4, raw_stack!F$2:F$99411, "Iya", raw_stack!G$2:G$99411, ">="&DATE(2026,1,1), raw_stack!G$2:G$99411, "<="&EOMONTH(DATE(2026,1,1),0) ), IF(_xlpm.x=0, "-", _xlpm.x) ) -> 46035 | AB4: =_xlfn.LET( _xlpm.x, _xlfn.MAXIFS( raw_stack!H$2:H$100000, raw_stack!D$2:D$100000, G4, raw_stack!F$2:F$100000, "Iya", raw_stack!G$2:G$100000, ">="&DATE(2026,1,1), raw_stack!G$2:G$100000, "<="&EOMONTH(DATE(2026,1,1),0) ), IF(OR(_xlpm.x=0, _xlpm.x=""), "-", _xlpm.x) ) -> 107336 | AC4: =_xlfn.LET( _xlpm.x, _xlfn.MAXIFS( raw_stack!G$2:G$99411, raw_stack!D$2:D$99411, G4, raw_stack!F$2:F$99411, "Iya", raw_stack!G$2:G$99411, ">="&DATE(2026,2,1), raw_stack!G$2:G$99411, "<="&EOMONTH(DATE(2026,2,1),0) ), IF(_xlpm.x=0, "-", _xlpm.x) ) -> - | AD4: =_xlfn.LET( _xlpm.x, _xlfn.MAXIFS( raw_stack!H$2:H$100000, raw_stack!D$2:D$100000, G4, raw_stack!F$2:F$100000, "Iya", raw_stack!G$2:G$100000, ">="&DATE(2026,2,1), raw_stack!G$2:G$100000, "<="&EOMONTH(DATE(2026,2,1),0) ), IF(OR(_xlpm.x=0, _xlpm.x=""), "-", _xlpm.x) ) -> - | AE4: =_xlfn.LET( _xlpm.x, _xlfn.MAXIFS( raw_stack!G$2:G$100000, raw_stack!D$2:D$100000, G4, raw_stack!F$2:F$100000, "Iya", raw_stack!G$2:G$100000, ">="&DATE(2026,3,1), raw_stack!G$2:G$100000, "<="&EOMONTH(DATE(2026,3,1),0) ), IF(_xlpm.x=0, "-", _xlpm.x) ) -> - | AF4: =_xlfn.LET( _xlpm.x, _xlfn.MAXIFS( raw_stack!H$2:H$100000, raw_stack!D$2:D$100000, G4, raw_stack!F$2:F$100000, "Iya", raw_stack!G$2:G$100000, ">="&DATE(2026,3,1), raw_stack!G$2:G$100000, "<="&EOMONTH(DATE(2026,3,1),0) ), IF(OR(_xlpm.x=0, _xlpm.x=""), "-", _xlpm.x) ) -> - | AG4: =_xlfn.LET( _xlpm.x, _xlfn.MAXIFS( raw_stack!G$2:G$100000, raw_stack!D$2:D$100000, G4, raw_stack!F$2:F$100000, "Iya", raw_stack!G$2:G$100000, ">="&DATE(2026,4,1), raw_stack!G$2:G$100000, "<="&EOMONTH(DATE(2026,4,1),0) ), IF(_xlpm.x=0, "-", _xlpm.x) ) -> - | AH4: =_xlfn.LET( _xlpm.x, _xlfn.MAXIFS( raw_stack!H$2:H$100000, raw_stack!D$2:D$100000, G4, raw_stack!F$2:F$100000, "Iya", raw_stack!G$2:G$100000, ">="&DATE(2026,4,1), raw_stack!G$2:G$100000, "<="&EOMONTH(DATE(2026,4,1),0) ), IF(OR(_xlpm.x=0, _xlpm.x=""), "-", _xlpm.x) ) -> -
A5: 4 | B5: =LEFT(D5,5) -> 89677 | C5: Vehicle Rent | D5: 89677 MAKASSAR | E5: Gran Max Pick Up (Badan) | F5: Sewa kendaraan operasional | G5: DD1709SU | H5: OPR | I5: PICKUP | J5: 4000000 | K5: 44988 | L5: 46083 | M5: 46083 | N5: ACTIVE | O5: =_xlfn.LET( _xlpm.x, _xlfn.MAXIFS( raw_stack!G$2:G$100000, raw_stack!D$2:D$100000, G5, raw_stack!F$2:F$100000, "Iya", raw_stack!G$2:G$100000, ">="&DATE(2025,7,1), raw_stack!G$2:G$100000, "<="&EOMONTH(DATE(2025,7,1),0) ), IF(_xlpm.x=0, "-", _xlpm.x) ) -> - | P5: =_xlfn.LET( _xlpm.x, _xlfn.MAXIFS( raw_stack!H$2:H$100000, raw_stack!D$2:D$100000, G5, raw_stack!F$2:F$100000, "Iya", raw_stack!G$2:G$100000, ">="&DATE(2025,7,1), raw_stack!G$2:G$100000, "<="&EOMONTH(DATE(2025,7,1),0) ), IF(OR(_xlpm.x=0, _xlpm.x=""), "-", _xlpm.x) ) -> - | Q5: =_xlfn.LET( _xlpm.x, _xlfn.MAXIFS( raw_stack!G$2:G$99411, raw_stack!D$2:D$99411, G5, raw_stack!F$2:F$99411, "Iya", raw_stack!G$2:G$99411, ">="&DATE(2025,8,1), raw_stack!G$2:G$99411, "<="&EOMONTH(DATE(2025,8,1),0) ), IF(_xlpm.x=0, "-", _xlpm.x) ) -> - | R5: =_xlfn.LET( _xlpm.x, _xlfn.MAXIFS( raw_stack!H$2:H$100000, raw_stack!D$2:D$100000, G5, raw_stack!F$2:F$100000, "Iya", raw_stack!G$2:G$100000, ">="&DATE(2025,8,1), raw_stack!G$2:G$100000, "<="&EOMONTH(DATE(2025,8,1),0) ), IF(OR(_xlpm.x=0, _xlpm.x=""), "-", _xlpm.x) ) -> - | S5: =_xlfn.LET( _xlpm.x, _xlfn.MAXIFS( raw_stack!G$2:G$99411, raw_stack!D$2:D$99411, G5, raw_stack!F$2:F$99411, "Iya", raw_stack!G$2:G$99411, ">="&DATE(2025,9,1), raw_stack!G$2:G$99411, "<="&EOMONTH(DATE(2025,9,1),0) ), IF(_xlpm.x=0, "-", _xlpm.x) ) -> - | T5: =_xlfn.LET( _xlpm.x, _xlfn.MAXIFS( raw_stack!H$2:H$100000, raw_stack!D$2:D$100000, G5, raw_stack!F$2:F$100000, "Iya", raw_stack!G$2:G$100000, ">="&DATE(2025,9,1), raw_stack!G$2:G$100000, "<="&EOMONTH(DATE(2025,9,1),0) ), IF(OR(_xlpm.x=0, _xlpm.x=""), "-", _xlpm.x) ) -> - | U5: =_xlfn.LET( _xlpm.x, _xlfn.MAXIFS( raw_stack!G$2:G$99411, raw_stack!D$2:D$99411, G5, raw_stack!F$2:F$99411, "Iya", raw_stack!G$2:G$99411, ">="&DATE(2025,10,1), raw_stack!G$2:G$99411, "<="&EOMONTH(DATE(2025,10,1),0) ), IF(_xlpm.x=0, "-", _xlpm.x) ) -> - | V5: =_xlfn.LET( _xlpm.x, _xlfn.MAXIFS( raw_stack!H$2:H$100000, raw_stack!D$2:D$100000, G5, raw_stack!F$2:F$100000, "Iya", raw_stack!G$2:G$100000, ">="&DATE(2025,10,1), raw_stack!G$2:G$100000, "<="&EOMONTH(DATE(2025,10,1),0) ), IF(OR(_xlpm.x=0, _xlpm.x=""), "-", _xlpm.x) ) -> - | W5: =_xlfn.LET( _xlpm.x, _xlfn.MAXIFS( raw_stack!G$2:G$99411, raw_stack!D$2:D$99411, G5, raw_stack!F$2:F$99411, "Iya", raw_stack!G$2:G$99411, ">="&DATE(2025,11,1), raw_stack!G$2:G$99411, "<="&EOMONTH(DATE(2025,11,1),0) ), IF(_xlpm.x=0, "-", _xlpm.x) ) -> 45986 | X5: =_xlfn.LET( _xlpm.x, _xlfn.MAXIFS( raw_stack!H$2:H$100000, raw_stack!D$2:D$100000, G5, raw_stack!F$2:F$100000, "Iya", raw_stack!G$2:G$100000, ">="&DATE(2025,11,1), raw_stack!G$2:G$100000, "<="&EOMONTH(DATE(2025,11,1),0) ), IF(OR(_xlpm.x=0, _xlpm.x=""), "-", _xlpm.x) ) -> 37103 | Y5: =_xlfn.LET( _xlpm.x, _xlfn.MAXIFS( raw_stack!G$2:G$99411, raw_stack!D$2:D$99411, G5, raw_stack!F$2:F$99411, "Iya", raw_stack!G$2:G$99411, ">="&DATE(2025,12,1), raw_stack!G$2:G$99411, "<="&EOMONTH(DATE(2025,12,1),0) ), IF(_xlpm.x=0, "-", _xlpm.x) ) -> - | Z5: =_xlfn.LET( _xlpm.x, _xlfn.MAXIFS( raw_stack!H$2:H$100000, raw_stack!D$2:D$100000, G5, raw_stack!F$2:F$100000, "Iya", raw_stack!G$2:G$100000, ">="&DATE(2025,12,1), raw_stack!G$2:G$100000, "<="&EOMONTH(DATE(2025,12,1),0) ), IF(OR(_xlpm.x=0, _xlpm.x=""), "-", _xlpm.x) ) -> - | AA5: =_xlfn.LET( _xlpm.x, _xlfn.MAXIFS( raw_stack!G$2:G$99411, raw_stack!D$2:D$99411, G5, raw_stack!F$2:F$99411, "Iya", raw_stack!G$2:G$99411, ">="&DATE(2026,1,1), raw_stack!G$2:G$99411, "<="&EOMONTH(DATE(2026,1,1),0) ), IF(_xlpm.x=0, "-", _xlpm.x) ) -> - | AB5: =_xlfn.LET( _xlpm.x, _xlfn.MAXIFS( raw_stack!H$2:H$100000, raw_stack!D$2:D$100000, G5, raw_stack!F$2:F$100000, "Iya", raw_stack!G$2:G$100000, ">="&DATE(2026,1,1), raw_stack!G$2:G$100000, "<="&EOMONTH(DATE(2026,1,1),0) ), IF(OR(_xlpm.x=0, _xlpm.x=""), "-", _xlpm.x) ) -> - | AC5: =_xlfn.LET( _xlpm.x, _xlfn.MAXIFS( raw_stack!G$2:G$99411, raw_stack!D$2:D$99411, G5, raw_stack!F$2:F$99411, "Iya", raw_stack!G$2:G$99411, ">="&DATE(2026,2,1), raw_stack!G$2:G$99411, "<="&EOMONTH(DATE(2026,2,1),0) ), IF(_xlpm.x=0, "-", _xlpm.x) ) -> - | AD5: =_xlfn.LET( _xlpm.x, _xlfn.MAXIFS( raw_stack!H$2:H$100000, raw_stack!D$2:D$100000, G5, raw_stack!F$2:F$100000, "Iya", raw_stack!G$2:G$100000, ">="&DATE(2026,2,1), raw_stack!G$2:G$100000, "<="&EOMONTH(DATE(2026,2,1),0) ), IF(OR(_xlpm.x=0, _xlpm.x=""), "-", _xlpm.x) ) -> - | AE5: =_xlfn.LET( _xlpm.x, _xlfn.MAXIFS( raw_stack!G$2:G$100000, raw_stack!D$2:D$100000, G5, raw_stack!F$2:F$100000, "Iya", raw_stack!G$2:G$100000, ">="&DATE(2026,3,1), raw_stack!G$2:G$100000, "<="&EOMONTH(DATE(2026,3,1),0) ), IF(_xlpm.x=0, "-", _xlpm.x) ) -> - | AF5: =_xlfn.LET( _xlpm.x, _xlfn.MAXIFS( raw_stack!H$2:H$100000, raw_stack!D$2:D$100000, G5, raw_stack!F$2:F$100000, "Iya", raw_stack!G$2:G$100000, ">="&DATE(2026,3,1), raw_stack!G$2:G$100000, "<="&EOMONTH(DATE(2026,3,1),0) ), IF(OR(_xlpm.x=0, _xlpm.x=""), "-", _xlpm.x) ) -> - | AG5: =_xlfn.LET( _xlpm.x, _xlfn.MAXIFS( raw_stack!G$2:G$100000, raw_stack!D$2:D$100000, G5, raw_stack!F$2:F$100000, "Iya", raw_stack!G$2:G$100000, ">="&DATE(2026,4,1), raw_stack!G$2:G$100000, "<="&EOMONTH(DATE(2026,4,1),0) ), IF(_xlpm.x=0, "-", _xlpm.x) ) -> - | AH5: =_xlfn.LET( _xlpm.x, _xlfn.MAXIFS( raw_stack!H$2:H$100000, raw_stack!D$2:D$100000, G5, raw_stack!F$2:F$100000, "Iya", raw_stack!G$2:G$100000, ">="&DATE(2026,4,1), raw_stack!G$2:G$100000, "<="&EOMONTH(DATE(2026,4,1),0) ), IF(OR(_xlpm.x=0, _xlpm.x=""), "-", _xlpm.x) ) -> -
A6: 5 | B6: =LEFT(D6,5) -> 89828 | C6: Vehicle Rent | D6: 89828 NAMLEA | E6: PICK UP TRAGA 2.5 4X2 MT D | F6: Sewa kendaraan operasional | G6: B3079BPJ | H6: OPR | I6: PICKUP | J6: 5950000 | K6: 45904 | L6: 46084 | M6: 46056 | N6: ACTIVE | O6: =_xlfn.LET( _xlpm.x, _xlfn.MAXIFS( raw_stack!G$2:G$100000, raw_stack!D$2:D$100000, G6, raw_stack!F$2:F$100000, "Iya", raw_stack!G$2:G$100000, ">="&DATE(2025,7,1), raw_stack!G$2:G$100000, "<="&EOMONTH(DATE(2025,7,1),0) ), IF(_xlpm.x=0, "-", _xlpm.x) ) -> - | P6: =_xlfn.LET( _xlpm.x, _xlfn.MAXIFS( raw_stack!H$2:H$100000, raw_stack!D$2:D$100000, G6, raw_stack!F$2:F$100000, "Iya", raw_stack!G$2:G$100000, ">="&DATE(2025,7,1), raw_stack!G$2:G$100000, "<="&EOMONTH(DATE(2025,7,1),0) ), IF(OR(_xlpm.x=0, _xlpm.x=""), "-", _xlpm.x) ) -> - | Q6: =_xlfn.LET( _xlpm.x, _xlfn.MAXIFS( raw_stack!G$2:G$99411, raw_stack!D$2:D$99411, G6, raw_stack!F$2:F$99411, "Iya", raw_stack!G$2:G$99411, ">="&DATE(2025,8,1), raw_stack!G$2:G$99411, "<="&EOMONTH(DATE(2025,8,1),0) ), IF(_xlpm.x=0, "-", _xlpm.x) ) -> 45889 | R6: =_xlfn.LET( _xlpm.x, _xlfn.MAXIFS( raw_stack!H$2:H$100000, raw_stack!D$2:D$100000, G6, raw_stack!F$2:F$100000, "Iya", raw_stack!G$2:G$100000, ">="&DATE(2025,8,1), raw_stack!G$2:G$100000, "<="&EOMONTH(DATE(2025,8,1),0) ), IF(OR(_xlpm.x=0, _xlpm.x=""), "-", _xlpm.x) ) -> 53445 | S6: =_xlfn.LET( _xlpm.x, _xlfn.MAXIFS( raw_stack!G$2:G$99411, raw_stack!D$2:D$99411, G6, raw_stack!F$2:F$99411, "Iya", raw_stack!G$2:G$99411, ">="&DATE(2025,9,1), raw_stack!G$2:G$99411, "<="&EOMONTH(DATE(2025,9,1),0) ), IF(_xlpm.x=0, "-", _xlpm.x) ) -> - | T6: =_xlfn.LET( _xlpm.x, _xlfn.MAXIFS( raw_stack!H$2:H$100000, raw_stack!D$2:D$100000, G6, raw_stack!F$2:F$100000, "Iya", raw_stack!G$2:G$100000, ">="&DATE(2025,9,1), raw_stack!G$2:G$100000, "<="&EOMONTH(DATE(2025,9,1),0) ), IF(OR(_xlpm.x=0, _xlpm.x=""), "-", _xlpm.x) ) -> - | U6: =_xlfn.LET( _xlpm.x, _xlfn.MAXIFS( raw_stack!G$2:G$99411, raw_stack!D$2:D$99411, G6, raw_stack!F$2:F$99411, "Iya", raw_stack!G$2:G$99411, ">="&DATE(2025,10,1), raw_stack!G$2:G$99411, "<="&EOMONTH(DATE(2025,10,1),0) ), IF(_xlpm.x=0, "-", _xlpm.x) ) -> - | V6: =_xlfn.LET( _xlpm.x, _xlfn.MAXIFS( raw_stack!H$2:H$100000, raw_stack!D$2:D$100000, G6, raw_stack!F$2:F$100000, "Iya", raw_stack!G$2:G$100000, ">="&DATE(2025,10,1), raw_stack!G$2:G$100000, "<="&EOMONTH(DATE(2025,10,1),0) ), IF(OR(_xlpm.x=0, _xlpm.x=""), "-", _xlpm.x) ) -> - | W6: =_xlfn.LET( _xlpm.x, _xlfn.MAXIFS( raw_stack!G$2:G$99411, raw_stack!D$2:D$99411, G6, raw_stack!F$2:F$99411, "Iya", raw_stack!G$2:G$99411, ">="&DATE(2025,11,1), raw_stack!G$2:G$99411, "<="&EOMONTH(DATE(2025,11,1),0) ), IF(_xlpm.x=0, "-", _xlpm.x) ) -> - | X6: =_xlfn.LET( _xlpm.x, _xlfn.MAXIFS( raw_stack!H$2:H$100000, raw_stack!D$2:D$100000, G6, raw_stack!F$2:F$100000, "Iya", raw_stack!G$2:G$100000, ">="&DATE(2025,11,1), raw_stack!G$2:G$100000, "<="&EOMONTH(DATE(2025,11,1),0) ), IF(OR(_xlpm.x=0, _xlpm.x=""), "-", _xlpm.x) ) -> - | Y6: =_xlfn.LET( _xlpm.x, _xlfn.MAXIFS( raw_stack!G$2:G$99411, raw_stack!D$2:D$99411, G6, raw_stack!F$2:F$99411, "Iya", raw_stack!G$2:G$99411, ">="&DATE(2025,12,1), raw_stack!G$2:G$99411, "<="&EOMONTH(DATE(2025,12,1),0) ), IF(_xlpm.x=0, "-", _xlpm.x) ) -> - | Z6: =_xlfn.LET( _xlpm.x, _xlfn.MAXIFS( raw_stack!H$2:H$100000, raw_stack!D$2:D$100000, G6, raw_stack!F$2:F$100000, "Iya", raw_stack!G$2:G$100000, ">="&DATE(2025,12,1), raw_stack!G$2:G$100000, "<="&EOMONTH(DATE(2025,12,1),0) ), IF(OR(_xlpm.x=0, _xlpm.x=""), "-", _xlpm.x) ) -> - | AA6: =_xlfn.LET( _xlpm.x, _xlfn.MAXIFS( raw_stack!G$2:G$99411, raw_stack!D$2:D$99411, G6, raw_stack!F$2:F$99411, "Iya", raw_stack!G$2:G$99411, ">="&DATE(2026,1,1), raw_stack!G$2:G$99411, "<="&EOMONTH(DATE(2026,1,1),0) ), IF(_xlpm.x=0, "-", _xlpm.x) ) -> 46028 | AB6: =_xlfn.LET( _xlpm.x, _xlfn.MAXIFS( raw_stack!H$2:H$100000, raw_stack!D$2:D$100000, G6, raw_stack!F$2:F$100000, "Iya", raw_stack!G$2:G$100000, ">="&DATE(2026,1,1), raw_stack!G$2:G$100000, "<="&EOMONTH(DATE(2026,1,1),0) ), IF(OR(_xlpm.x=0, _xlpm.x=""), "-", _xlpm.x) ) -> 55586 | AC6: =_xlfn.LET( _xlpm.x, _xlfn.MAXIFS( raw_stack!G$2:G$99411, raw_stack!D$2:D$99411, G6, raw_stack!F$2:F$99411, "Iya", raw_stack!G$2:G$99411, ">="&DATE(2026,2,1), raw_stack!G$2:G$99411, "<="&EOMONTH(DATE(2026,2,1),0) ), IF(_xlpm.x=0, "-", _xlpm.x) ) -> - | AD6: =_xlfn.LET( _xlpm.x, _xlfn.MAXIFS( raw_stack!H$2:H$100000, raw_stack!D$2:D$100000, G6, raw_stack!F$2:F$100000, "Iya", raw_stack!G$2:G$100000, ">="&DATE(2026,2,1), raw_stack!G$2:G$100000, "<="&EOMONTH(DATE(2026,2,1),0) ), IF(OR(_xlpm.x=0, _xlpm.x=""), "-", _xlpm.x) ) -> - | AE6: =_xlfn.LET( _xlpm.x, _xlfn.MAXIFS( raw_stack!G$2:G$100000, raw_stack!D$2:D$100000, G6, raw_stack!F$2:F$100000, "Iya", raw_stack!G$2:G$100000, ">="&DATE(2026,3,1), raw_stack!G$2:G$100000, "<="&EOMONTH(DATE(2026,3,1),0) ), IF(_xlpm.x=0, "-", _xlpm.x) ) -> - | AF6: =_xlfn.LET( _xlpm.x, _xlfn.MAXIFS( raw_stack!H$2:H$100000, raw_stack!D$2:D$100000, G6, raw_stack!F$2:F$100000, "Iya", raw_stack!G$2:G$100000, ">="&DATE(2026,3,1), raw_stack!G$2:G$100000, "<="&EOMONTH(DATE(2026,3,1),0) ), IF(OR(_xlpm.x=0, _xlpm.x=""), "-", _xlpm.x) ) -> - | AG6: =_xlfn.LET( _xlpm.x, _xlfn.MAXIFS( raw_stack!G$2:G$100000, raw_stack!D$2:D$100000, G6, raw_stack!F$2:F$100000, "Iya", raw_stack!G$2:G$100000, ">="&DATE(2026,4,1), raw_stack!G$2:G$100000, "<="&EOMONTH(DATE(2026,4,1),0) ), IF(_xlpm.x=0, "-", _xlpm.x) ) -> - | AH6: =_xlfn.LET( _xlpm.x, _xlfn.MAXIFS( raw_stack!H$2:H$100000, raw_stack!D$2:D$100000, G6, raw_stack!F$2:F$100000, "Iya", raw_stack!G$2:G$100000, ">="&DATE(2026,4,1), raw_stack!G$2:G$100000, "<="&EOMONTH(DATE(2026,4,1),0) ), IF(OR(_xlpm.x=0, _xlpm.x=""), "-", _xlpm.x) ) -> -
